DEBUG:root:8
INFO:django.utils.autoreload:C:\Users\igoro\OneDrive\Documentos\GitHub\infoPizza\app\views.py changed, reloading.
DEBUG:root:9
INFO:django.utils.autoreload:C:\Users\igoro\OneDrive\Documentos\GitHub\infoPizza\app\views.py changed, reloading.
DEBUG:root:10
ERROR:django.request:Internal Server Error: /pedido/ajax/tamanho
Traceback (most recent call last):
  File "C:\Users\igoro\AppData\Local\Programs\Python\Python310\lib\site-packages\django\core\handlers\exception.py", line 55, in inner
    response = get_response(request)
  File "C:\Users\igoro\AppData\Local\Programs\Python\Python310\lib\site-packages\django\core\handlers\base.py", line 197, in _get_response
    response = wrapped_callback(request, *callback_args, **callback_kwargs)
  File "C:\Users\igoro\OneDrive\Documentos\GitHub\infoPizza\app\views.py", line 249, in load_tamanho
    tamanho = ItensPedido.objects.filter(id=itensPedido_id).values_list('tamanho',flat=True)[0]
  File "C:\Users\igoro\AppData\Local\Programs\Python\Python310\lib\site-packages\django\db\models\query.py", line 362, in __getitem__
    return qs._result_cache[0]
IndexError: list index out of range
ERROR:django.request:Internal Server Error: /pedido/ajax/tamanho
Traceback (most recent call last):
  File "C:\Users\igoro\AppData\Local\Programs\Python\Python310\lib\site-packages\django\core\handlers\exception.py", line 55, in inner
    response = get_response(request)
  File "C:\Users\igoro\AppData\Local\Programs\Python\Python310\lib\site-packages\django\core\handlers\base.py", line 197, in _get_response
    response = wrapped_callback(request, *callback_args, **callback_kwargs)
  File "C:\Users\igoro\OneDrive\Documentos\GitHub\infoPizza\app\views.py", line 249, in load_tamanho
    tamanho = ItensPedido.objects.filter(id=itensPedido_id).values_list('tamanho',flat=True)[0]
  File "C:\Users\igoro\AppData\Local\Programs\Python\Python310\lib\site-packages\django\db\models\query.py", line 362, in __getitem__
    return qs._result_cache[0]
IndexError: list index out of range
INFO:django.utils.autoreload:C:\Users\igoro\OneDrive\Documentos\GitHub\infoPizza\app\views.py changed, reloading.
DEBUG:root:11
ERROR:django.request:Internal Server Error: /pedido/ajax/tamanho
Traceback (most recent call last):
  File "C:\Users\igoro\AppData\Local\Programs\Python\Python310\lib\site-packages\django\core\handlers\exception.py", line 55, in inner
    response = get_response(request)
  File "C:\Users\igoro\AppData\Local\Programs\Python\Python310\lib\site-packages\django\core\handlers\base.py", line 197, in _get_response
    response = wrapped_callback(request, *callback_args, **callback_kwargs)
  File "C:\Users\igoro\OneDrive\Documentos\GitHub\infoPizza\app\views.py", line 249, in load_tamanho
    tamanho = ItensPedido.objects.filter(id=itensPedido_id).values_list('tamanho',flat=True)[0]
  File "C:\Users\igoro\AppData\Local\Programs\Python\Python310\lib\site-packages\django\db\models\query.py", line 362, in __getitem__
    return qs._result_cache[0]
IndexError: list index out of range
ERROR:django.request:Internal Server Error: /pedido/ajax/tamanho
Traceback (most recent call last):
  File "C:\Users\igoro\AppData\Local\Programs\Python\Python310\lib\site-packages\django\core\handlers\exception.py", line 55, in inner
    response = get_response(request)
  File "C:\Users\igoro\AppData\Local\Programs\Python\Python310\lib\site-packages\django\core\handlers\base.py", line 197, in _get_response
    response = wrapped_callback(request, *callback_args, **callback_kwargs)
  File "C:\Users\igoro\OneDrive\Documentos\GitHub\infoPizza\app\views.py", line 249, in load_tamanho
    tamanho = ItensPedido.objects.filter(id=itensPedido_id).values_list('tamanho',flat=True)[0]
  File "C:\Users\igoro\AppData\Local\Programs\Python\Python310\lib\site-packages\django\db\models\query.py", line 362, in __getitem__
    return qs._result_cache[0]
IndexError: list index out of range
INFO:django.utils.autoreload:C:\Users\igoro\OneDrive\Documentos\GitHub\infoPizza\app\views.py changed, reloading.
DEBUG:root:<app.forms.MesaChoiceField object at 0x000001FA5CA1E4D0>
ERROR:django.request:Internal Server Error: /pedido/ajax/tamanho
Traceback (most recent call last):
  File "C:\Users\igoro\AppData\Local\Programs\Python\Python310\lib\site-packages\django\core\handlers\exception.py", line 55, in inner
    response = get_response(request)
  File "C:\Users\igoro\AppData\Local\Programs\Python\Python310\lib\site-packages\django\core\handlers\base.py", line 197, in _get_response
    response = wrapped_callback(request, *callback_args, **callback_kwargs)
  File "C:\Users\igoro\OneDrive\Documentos\GitHub\infoPizza\app\views.py", line 249, in load_tamanho
    tamanho = ItensPedido.objects.filter(id=itensPedido_id).values_list('tamanho',flat=True)[0]
  File "C:\Users\igoro\AppData\Local\Programs\Python\Python310\lib\site-packages\django\db\models\query.py", line 362, in __getitem__
    return qs._result_cache[0]
IndexError: list index out of range
ERROR:django.request:Internal Server Error: /pedido/ajax/tamanho
Traceback (most recent call last):
  File "C:\Users\igoro\AppData\Local\Programs\Python\Python310\lib\site-packages\django\core\handlers\exception.py", line 55, in inner
    response = get_response(request)
  File "C:\Users\igoro\AppData\Local\Programs\Python\Python310\lib\site-packages\django\core\handlers\base.py", line 197, in _get_response
    response = wrapped_callback(request, *callback_args, **callback_kwargs)
  File "C:\Users\igoro\OneDrive\Documentos\GitHub\infoPizza\app\views.py", line 249, in load_tamanho
    tamanho = ItensPedido.objects.filter(id=itensPedido_id).values_list('tamanho',flat=True)[0]
  File "C:\Users\igoro\AppData\Local\Programs\Python\Python310\lib\site-packages\django\db\models\query.py", line 362, in __getitem__
    return qs._result_cache[0]
IndexError: list index out of range
INFO:django.utils.autoreload:C:\Users\igoro\OneDrive\Documentos\GitHub\infoPizza\app\views.py changed, reloading.
INFO:django.utils.autoreload:C:\Users\igoro\OneDrive\Documentos\GitHub\infoPizza\app\views.py changed, reloading.
INFO:django.utils.autoreload:C:\Users\igoro\OneDrive\Documentos\GitHub\infoPizza\app\models.py changed, reloading.
INFO:django.utils.autoreload:C:\Users\igoro\OneDrive\Documentos\GitHub\infoPizza\app\views.py changed, reloading.
ERROR:django.request:Internal Server Error: /pedido/ajax/tamanho
Traceback (most recent call last):
  File "C:\Users\igoro\AppData\Local\Programs\Python\Python310\lib\site-packages\django\core\handlers\exception.py", line 55, in inner
    response = get_response(request)
  File "C:\Users\igoro\AppData\Local\Programs\Python\Python310\lib\site-packages\django\core\handlers\base.py", line 197, in _get_response
    response = wrapped_callback(request, *callback_args, **callback_kwargs)
  File "C:\Users\igoro\OneDrive\Documentos\GitHub\infoPizza\app\views.py", line 245, in load_tamanho
    tamanho = ItensPedido.objects.filter(id=itensPedido_id).values_list('tamanho',flat=True)[0]
  File "C:\Users\igoro\AppData\Local\Programs\Python\Python310\lib\site-packages\django\db\models\query.py", line 362, in __getitem__
    return qs._result_cache[0]
IndexError: list index out of range
ERROR:django.request:Internal Server Error: /pedido/ajax/tamanho
Traceback (most recent call last):
  File "C:\Users\igoro\AppData\Local\Programs\Python\Python310\lib\site-packages\django\core\handlers\exception.py", line 55, in inner
    response = get_response(request)
  File "C:\Users\igoro\AppData\Local\Programs\Python\Python310\lib\site-packages\django\core\handlers\base.py", line 197, in _get_response
    response = wrapped_callback(request, *callback_args, **callback_kwargs)
  File "C:\Users\igoro\OneDrive\Documentos\GitHub\infoPizza\app\views.py", line 245, in load_tamanho
    tamanho = ItensPedido.objects.filter(id=itensPedido_id).values_list('tamanho',flat=True)[0]
  File "C:\Users\igoro\AppData\Local\Programs\Python\Python310\lib\site-packages\django\db\models\query.py", line 362, in __getitem__
    return qs._result_cache[0]
IndexError: list index out of range
INFO:django.utils.autoreload:C:\Users\igoro\OneDrive\Documentos\GitHub\infoPizza\app\forms.py changed, reloading.
