DEBUG:root:Cliente object (1)
ERROR:django.request:Internal Server Error: /pedido/form/9
Traceback (most recent call last):
  File "C:\Users\igoro\AppData\Local\Programs\Python\Python310\lib\site-packages\django\db\models\fields\__init__.py", line 1988, in get_prep_value
    return int(value)
TypeError: int() argument must be a string, a bytes-like object or a real number, not 'Cliente'

The above exception was the direct cause of the following exception:

Traceback (most recent call last):
  File "C:\Users\igoro\AppData\Local\Programs\Python\Python310\lib\site-packages\django\core\handlers\exception.py", line 55, in inner
    response = get_response(request)
  File "C:\Users\igoro\AppData\Local\Programs\Python\Python310\lib\site-packages\django\core\handlers\base.py", line 197, in _get_response
    response = wrapped_callback(request, *callback_args, **callback_kwargs)
  File "C:\Users\igoro\OneDrive\Documentos\GitHub\infoPizza\app\views.py", line 242, in pedidosUpdate
    cliente = Cliente.objects.get(id=pedido.cliente)
  File "C:\Users\igoro\AppData\Local\Programs\Python\Python310\lib\site-packages\django\db\models\manager.py", line 85, in manager_method
    return getattr(self.get_queryset(), name)(*args, **kwargs)
  File "C:\Users\igoro\AppData\Local\Programs\Python\Python310\lib\site-packages\django\db\models\query.py", line 482, in get
    clone = self._chain() if self.query.combinator else self.filter(*args, **kwargs)
  File "C:\Users\igoro\AppData\Local\Programs\Python\Python310\lib\site-packages\django\db\models\query.py", line 1071, in filter
    return self._filter_or_exclude(False, args, kwargs)
  File "C:\Users\igoro\AppData\Local\Programs\Python\Python310\lib\site-packages\django\db\models\query.py", line 1089, in _filter_or_exclude
    clone._filter_or_exclude_inplace(negate, args, kwargs)
  File "C:\Users\igoro\AppData\Local\Programs\Python\Python310\lib\site-packages\django\db\models\query.py", line 1096, in _filter_or_exclude_inplace
    self._query.add_q(Q(*args, **kwargs))
  File "C:\Users\igoro\AppData\Local\Programs\Python\Python310\lib\site-packages\django\db\models\sql\query.py", line 1502, in add_q
    clause, _ = self._add_q(q_object, self.used_aliases)
  File "C:\Users\igoro\AppData\Local\Programs\Python\Python310\lib\site-packages\django\db\models\sql\query.py", line 1532, in _add_q
    child_clause, needed_inner = self.build_filter(
  File "C:\Users\igoro\AppData\Local\Programs\Python\Python310\lib\site-packages\django\db\models\sql\query.py", line 1448, in build_filter
    condition = self.build_lookup(lookups, col, value)
  File "C:\Users\igoro\AppData\Local\Programs\Python\Python310\lib\site-packages\django\db\models\sql\query.py", line 1273, in build_lookup
    lookup = lookup_class(lhs, rhs)
  File "C:\Users\igoro\AppData\Local\Programs\Python\Python310\lib\site-packages\django\db\models\lookups.py", line 27, in __init__
    self.rhs = self.get_prep_lookup()
  File "C:\Users\igoro\AppData\Local\Programs\Python\Python310\lib\site-packages\django\db\models\lookups.py", line 85, in get_prep_lookup
    return self.lhs.output_field.get_prep_value(self.rhs)
  File "C:\Users\igoro\AppData\Local\Programs\Python\Python310\lib\site-packages\django\db\models\fields\__init__.py", line 1990, in get_prep_value
    raise e.__class__(
TypeError: Field 'id' expected a number but got <Cliente: Cliente object (1)>.
INFO:django.utils.autoreload:C:\Users\igoro\OneDrive\Documentos\GitHub\infoPizza\app\views.py changed, reloading.
DEBUG:root:Cliente object (1)
ERROR:django.request:Internal Server Error: /pedido/form/9
Traceback (most recent call last):
  File "C:\Users\igoro\AppData\Local\Programs\Python\Python310\lib\site-packages\django\core\handlers\exception.py", line 55, in inner
    response = get_response(request)
  File "C:\Users\igoro\AppData\Local\Programs\Python\Python310\lib\site-packages\django\core\handlers\base.py", line 197, in _get_response
    response = wrapped_callback(request, *callback_args, **callback_kwargs)
  File "C:\Users\igoro\OneDrive\Documentos\GitHub\infoPizza\app\views.py", line 243, in pedidosUpdate
    cliente = Cliente.objects.get(id=pdd.cliente)
AttributeError: 'QuerySet' object has no attribute 'cliente'
INFO:django.utils.autoreload:C:\Users\igoro\OneDrive\Documentos\GitHub\infoPizza\app\views.py changed, reloading.
DEBUG:root:Cliente object (1)
DEBUG:root:None
ERROR:django.request:Internal Server Error: /pedido/form/6
Traceback (most recent call last):
  File "C:\Users\igoro\AppData\Local\Programs\Python\Python310\lib\site-packages\django\core\handlers\exception.py", line 55, in inner
    response = get_response(request)
  File "C:\Users\igoro\AppData\Local\Programs\Python\Python310\lib\site-packages\django\core\handlers\base.py", line 197, in _get_response
    response = wrapped_callback(request, *callback_args, **callback_kwargs)
  File "C:\Users\igoro\OneDrive\Documentos\GitHub\infoPizza\app\views.py", line 243, in pedidosUpdate
    cliente = Cliente.objects.get(id=cliente_id)
  File "C:\Users\igoro\AppData\Local\Programs\Python\Python310\lib\site-packages\django\db\models\manager.py", line 85, in manager_method
    return getattr(self.get_queryset(), name)(*args, **kwargs)
  File "C:\Users\igoro\AppData\Local\Programs\Python\Python310\lib\site-packages\django\db\models\query.py", line 496, in get
    raise self.model.DoesNotExist(
app.models.Cliente.DoesNotExist: Cliente matching query does not exist.
INFO:django.utils.autoreload:C:\Users\igoro\OneDrive\Documentos\GitHub\infoPizza\app\views.py changed, reloading.
DEBUG:root:None
ERROR:django.request:Internal Server Error: /pedido/form/6
Traceback (most recent call last):
  File "C:\Users\igoro\AppData\Local\Programs\Python\Python310\lib\site-packages\django\core\handlers\exception.py", line 55, in inner
    response = get_response(request)
  File "C:\Users\igoro\AppData\Local\Programs\Python\Python310\lib\site-packages\django\core\handlers\base.py", line 197, in _get_response
    response = wrapped_callback(request, *callback_args, **callback_kwargs)
  File "C:\Users\igoro\OneDrive\Documentos\GitHub\infoPizza\app\views.py", line 243, in pedidosUpdate
    if cliente_id > 0:
TypeError: '>' not supported between instances of 'NoneType' and 'int'
INFO:django.utils.autoreload:C:\Users\igoro\OneDrive\Documentos\GitHub\infoPizza\app\views.py changed, reloading.
DEBUG:root:None
DEBUG:root:Cliente object (1)
DEBUG:root:None
INFO:django.utils.autoreload:C:\Users\igoro\OneDrive\Documentos\GitHub\infoPizza\app\views.py changed, reloading.
DEBUG:root:Cliente object (1)
INFO:django.utils.autoreload:C:\Users\igoro\OneDrive\Documentos\GitHub\infoPizza\app\views.py changed, reloading.
DEBUG:root:Cliente object (1)
DEBUG:root:None
DEBUG:root:None
DEBUG:root:Cliente object (1)
DEBUG:root:Cliente object (1)
DEBUG:root:None
ERROR:django.request:Internal Server Error: /pedido/delivery/form/
Traceback (most recent call last):
  File "C:\Users\igoro\AppData\Local\Programs\Python\Python310\lib\site-packages\django\template\base.py", line 505, in parse
    compile_func = self.tags[command]
KeyError: 'else'

During handling of the above exception, another exception occurred:

Traceback (most recent call last):
  File "C:\Users\igoro\AppData\Local\Programs\Python\Python310\lib\site-packages\django\core\handlers\exception.py", line 55, in inner
    response = get_response(request)
  File "C:\Users\igoro\AppData\Local\Programs\Python\Python310\lib\site-packages\django\core\handlers\base.py", line 197, in _get_response
    response = wrapped_callback(request, *callback_args, **callback_kwargs)
  File "C:\Users\igoro\OneDrive\Documentos\GitHub\infoPizza\app\views.py", line 193, in pedidosDeliveryInsert
    return render(request,'pedido/form.html', {'form':form, 'form2':form2, 'form3':form3,'titulo':'Anotar Pedido - Delivery'})
  File "C:\Users\igoro\AppData\Local\Programs\Python\Python310\lib\site-packages\django\shortcuts.py", line 24, in render
    content = loader.render_to_string(template_name, context, request, using=using)
  File "C:\Users\igoro\AppData\Local\Programs\Python\Python310\lib\site-packages\django\template\loader.py", line 61, in render_to_string
    template = get_template(template_name, using=using)
  File "C:\Users\igoro\AppData\Local\Programs\Python\Python310\lib\site-packages\django\template\loader.py", line 15, in get_template
    return engine.get_template(template_name)
  File "C:\Users\igoro\AppData\Local\Programs\Python\Python310\lib\site-packages\django\template\backends\django.py", line 34, in get_template
    return Template(self.engine.get_template(template_name), self)
  File "C:\Users\igoro\AppData\Local\Programs\Python\Python310\lib\site-packages\django\template\engine.py", line 176, in get_template
    template, origin = self.find_template(template_name)
  File "C:\Users\igoro\AppData\Local\Programs\Python\Python310\lib\site-packages\django\template\engine.py", line 158, in find_template
    template = loader.get_template(name, skip=skip)
  File "C:\Users\igoro\AppData\Local\Programs\Python\Python310\lib\site-packages\django\template\loaders\base.py", line 28, in get_template
    return Template(
  File "C:\Users\igoro\AppData\Local\Programs\Python\Python310\lib\site-packages\django\template\base.py", line 154, in __init__
    self.nodelist = self.compile_nodelist()
  File "C:\Users\igoro\AppData\Local\Programs\Python\Python310\lib\site-packages\django\template\base.py", line 200, in compile_nodelist
    return parser.parse()
  File "C:\Users\igoro\AppData\Local\Programs\Python\Python310\lib\site-packages\django\template\base.py", line 507, in parse
    self.invalid_block_tag(token, command, parse_until)
  File "C:\Users\igoro\AppData\Local\Programs\Python\Python310\lib\site-packages\django\template\base.py", line 568, in invalid_block_tag
    raise self.error(
django.template.exceptions.TemplateSyntaxError: Invalid block tag on line 30: 'else'. Did you forget to register or load this tag?
ERROR:django.request:Internal Server Error: /pedido/ajax/tamanho
Traceback (most recent call last):
  File "C:\Users\igoro\AppData\Local\Programs\Python\Python310\lib\site-packages\django\core\handlers\exception.py", line 55, in inner
    response = get_response(request)
  File "C:\Users\igoro\AppData\Local\Programs\Python\Python310\lib\site-packages\django\core\handlers\base.py", line 197, in _get_response
    response = wrapped_callback(request, *callback_args, **callback_kwargs)
  File "C:\Users\igoro\OneDrive\Documentos\GitHub\infoPizza\app\views.py", line 261, in load_tamanho
    tamanho = ItensPedido.objects.filter(id=itensPedido_id).values_list('tamanho',flat=True)[0]
  File "C:\Users\igoro\AppData\Local\Programs\Python\Python310\lib\site-packages\django\db\models\query.py", line 362, in __getitem__
    return qs._result_cache[0]
IndexError: list index out of range
DEBUG:root:Cliente object (1)
ERROR:django.request:Internal Server Error: /pedido/form/15
Traceback (most recent call last):
  File "C:\Users\igoro\AppData\Local\Programs\Python\Python310\lib\site-packages\django\core\handlers\exception.py", line 55, in inner
    response = get_response(request)
  File "C:\Users\igoro\AppData\Local\Programs\Python\Python310\lib\site-packages\django\core\handlers\base.py", line 197, in _get_response
    response = wrapped_callback(request, *callback_args, **callback_kwargs)
  File "C:\Users\igoro\OneDrive\Documentos\GitHub\infoPizza\app\views.py", line 252, in pedidosUpdate
    return render(request,'pedido/form.html',{'form':form, 'form2':form2, 'form3':form3,'pedido':pedido,'clienteinfo':clienteinfo,'titulo':titulo})
UnboundLocalError: local variable 'clienteinfo' referenced before assignment
INFO:django.utils.autoreload:C:\Users\igoro\OneDrive\Documentos\GitHub\infoPizza\app\forms.py changed, reloading.
DEBUG:root:Cliente object (1)
INFO:django.utils.autoreload:C:\Users\igoro\OneDrive\Documentos\GitHub\infoPizza\app\forms.py changed, reloading.
DEBUG:root:Cliente object (1)
DEBUG:root:Cliente object (1)
INFO:django.utils.autoreload:C:\Users\igoro\OneDrive\Documentos\GitHub\infoPizza\app\forms.py changed, reloading.
DEBUG:root:Cliente object (1)
DEBUG:root:Cliente object (1)
INFO:django.utils.autoreload:C:\Users\igoro\OneDrive\Documentos\GitHub\infoPizza\app\forms.py changed, reloading.
