DEBUG:root:Cliente object (1)
ERROR:django.request:Internal Server Error: /pedido/form/9
Traceback (most recent call last):
  File "C:\Users\igoro\AppData\Local\Programs\Python\Python310\lib\site-packages\django\db\models\fields\__init__.py", line 1988, in get_prep_value
    return int(value)
TypeError: int() argument must be a string, a bytes-like object or a real number, not 'Cliente'

The above exception was the direct cause of the following exception:

Traceback (most recent call last):
  File "C:\Users\igoro\AppData\Local\Programs\Python\Python310\lib\site-packages\django\core\handlers\exception.py", line 55, in inner
    response = get_response(request)
  File "C:\Users\igoro\AppData\Local\Programs\Python\Python310\lib\site-packages\django\core\handlers\base.py", line 197, in _get_response
    response = wrapped_callback(request, *callback_args, **callback_kwargs)
  File "C:\Users\igoro\OneDrive\Documentos\GitHub\infoPizza\app\views.py", line 242, in pedidosUpdate
    cliente = Cliente.objects.get(id=pedido.cliente)
  File "C:\Users\igoro\AppData\Local\Programs\Python\Python310\lib\site-packages\django\db\models\manager.py", line 85, in manager_method
    return getattr(self.get_queryset(), name)(*args, **kwargs)
  File "C:\Users\igoro\AppData\Local\Programs\Python\Python310\lib\site-packages\django\db\models\query.py", line 482, in get
    clone = self._chain() if self.query.combinator else self.filter(*args, **kwargs)
  File "C:\Users\igoro\AppData\Local\Programs\Python\Python310\lib\site-packages\django\db\models\query.py", line 1071, in filter
    return self._filter_or_exclude(False, args, kwargs)
  File "C:\Users\igoro\AppData\Local\Programs\Python\Python310\lib\site-packages\django\db\models\query.py", line 1089, in _filter_or_exclude
    clone._filter_or_exclude_inplace(negate, args, kwargs)
  File "C:\Users\igoro\AppData\Local\Programs\Python\Python310\lib\site-packages\django\db\models\query.py", line 1096, in _filter_or_exclude_inplace
    self._query.add_q(Q(*args, **kwargs))
  File "C:\Users\igoro\AppData\Local\Programs\Python\Python310\lib\site-packages\django\db\models\sql\query.py", line 1502, in add_q
    clause, _ = self._add_q(q_object, self.used_aliases)
  File "C:\Users\igoro\AppData\Local\Programs\Python\Python310\lib\site-packages\django\db\models\sql\query.py", line 1532, in _add_q
    child_clause, needed_inner = self.build_filter(
  File "C:\Users\igoro\AppData\Local\Programs\Python\Python310\lib\site-packages\django\db\models\sql\query.py", line 1448, in build_filter
    condition = self.build_lookup(lookups, col, value)
  File "C:\Users\igoro\AppData\Local\Programs\Python\Python310\lib\site-packages\django\db\models\sql\query.py", line 1273, in build_lookup
    lookup = lookup_class(lhs, rhs)
  File "C:\Users\igoro\AppData\Local\Programs\Python\Python310\lib\site-packages\django\db\models\lookups.py", line 27, in __init__
    self.rhs = self.get_prep_lookup()
  File "C:\Users\igoro\AppData\Local\Programs\Python\Python310\lib\site-packages\django\db\models\lookups.py", line 85, in get_prep_lookup
    return self.lhs.output_field.get_prep_value(self.rhs)
  File "C:\Users\igoro\AppData\Local\Programs\Python\Python310\lib\site-packages\django\db\models\fields\__init__.py", line 1990, in get_prep_value
    raise e.__class__(
TypeError: Field 'id' expected a number but got <Cliente: Cliente object (1)>.
INFO:django.utils.autoreload:C:\Users\igoro\OneDrive\Documentos\GitHub\infoPizza\app\views.py changed, reloading.
DEBUG:root:Cliente object (1)
ERROR:django.request:Internal Server Error: /pedido/form/9
Traceback (most recent call last):
  File "C:\Users\igoro\AppData\Local\Programs\Python\Python310\lib\site-packages\django\core\handlers\exception.py", line 55, in inner
    response = get_response(request)
  File "C:\Users\igoro\AppData\Local\Programs\Python\Python310\lib\site-packages\django\core\handlers\base.py", line 197, in _get_response
    response = wrapped_callback(request, *callback_args, **callback_kwargs)
  File "C:\Users\igoro\OneDrive\Documentos\GitHub\infoPizza\app\views.py", line 243, in pedidosUpdate
    cliente = Cliente.objects.get(id=pdd.cliente)
AttributeError: 'QuerySet' object has no attribute 'cliente'
INFO:django.utils.autoreload:C:\Users\igoro\OneDrive\Documentos\GitHub\infoPizza\app\views.py changed, reloading.
DEBUG:root:Cliente object (1)
DEBUG:root:None
ERROR:django.request:Internal Server Error: /pedido/form/6
Traceback (most recent call last):
  File "C:\Users\igoro\AppData\Local\Programs\Python\Python310\lib\site-packages\django\core\handlers\exception.py", line 55, in inner
    response = get_response(request)
  File "C:\Users\igoro\AppData\Local\Programs\Python\Python310\lib\site-packages\django\core\handlers\base.py", line 197, in _get_response
    response = wrapped_callback(request, *callback_args, **callback_kwargs)
  File "C:\Users\igoro\OneDrive\Documentos\GitHub\infoPizza\app\views.py", line 243, in pedidosUpdate
    cliente = Cliente.objects.get(id=cliente_id)
  File "C:\Users\igoro\AppData\Local\Programs\Python\Python310\lib\site-packages\django\db\models\manager.py", line 85, in manager_method
    return getattr(self.get_queryset(), name)(*args, **kwargs)
  File "C:\Users\igoro\AppData\Local\Programs\Python\Python310\lib\site-packages\django\db\models\query.py", line 496, in get
    raise self.model.DoesNotExist(
app.models.Cliente.DoesNotExist: Cliente matching query does not exist.
INFO:django.utils.autoreload:C:\Users\igoro\OneDrive\Documentos\GitHub\infoPizza\app\views.py changed, reloading.
DEBUG:root:None
ERROR:django.request:Internal Server Error: /pedido/form/6
Traceback (most recent call last):
  File "C:\Users\igoro\AppData\Local\Programs\Python\Python310\lib\site-packages\django\core\handlers\exception.py", line 55, in inner
    response = get_response(request)
  File "C:\Users\igoro\AppData\Local\Programs\Python\Python310\lib\site-packages\django\core\handlers\base.py", line 197, in _get_response
    response = wrapped_callback(request, *callback_args, **callback_kwargs)
  File "C:\Users\igoro\OneDrive\Documentos\GitHub\infoPizza\app\views.py", line 243, in pedidosUpdate
    if cliente_id > 0:
TypeError: '>' not supported between instances of 'NoneType' and 'int'
INFO:django.utils.autoreload:C:\Users\igoro\OneDrive\Documentos\GitHub\infoPizza\app\views.py changed, reloading.
DEBUG:root:None
DEBUG:root:Cliente object (1)
DEBUG:root:None
INFO:django.utils.autoreload:C:\Users\igoro\OneDrive\Documentos\GitHub\infoPizza\app\views.py changed, reloading.
DEBUG:root:Cliente object (1)
INFO:django.utils.autoreload:C:\Users\igoro\OneDrive\Documentos\GitHub\infoPizza\app\views.py changed, reloading.
DEBUG:root:Cliente object (1)
DEBUG:root:None
DEBUG:root:None
