DEBUG:root:
INFO:django.utils.autoreload:C:\Projetos\InfoPizza\app\views.py changed, reloading.
DEBUG:root:[{}]
INFO:django.utils.autoreload:C:\Projetos\InfoPizza\app\views.py changed, reloading.
DEBUG:root:[{}]
INFO:django.utils.autoreload:C:\Projetos\InfoPizza\app\views.py changed, reloading.
DEBUG:root:<bound method BaseForm.is_valid of <PedidoForm bound=True, valid=Unknown, fields=(metodoPag;obs;cliente)>>
DEBUG:root:<bound method BaseFormSet.is_valid of <django.forms.formsets.ItensPedidoFormFormSet object at 0x000002DE15759A50>>
DEBUG:root:<bound method BaseFormSet.is_valid of <django.forms.formsets.ItensPedidoFormFormSet object at 0x000002DE1575A3B0>>
DEBUG:root:<bound method BaseForm.is_valid of <PedidoForm bound=True, valid=Unknown, fields=(metodoPag;obs;cliente)>>
DEBUG:root:<bound method BaseFormSet.is_valid of <django.forms.formsets.ItensPedidoFormFormSet object at 0x000002DE158B0790>>
DEBUG:root:<bound method BaseFormSet.is_valid of <django.forms.formsets.ItensPedidoFormFormSet object at 0x000002DE158B3F40>>
DEBUG:root:<bound method BaseForm.is_valid of <PedidoForm bound=True, valid=Unknown, fields=(metodoPag;obs;cliente)>>
DEBUG:root:<bound method BaseFormSet.is_valid of <django.forms.formsets.ItensPedidoFormFormSet object at 0x000002DE157F71F0>>
DEBUG:root:<bound method BaseFormSet.is_valid of <django.forms.formsets.ItensPedidoFormFormSet object at 0x000002DE157F5B40>>
DEBUG:root:<bound method BaseForm.is_valid of <PedidoForm bound=True, valid=Unknown, fields=(metodoPag;obs;cliente)>>
DEBUG:root:<bound method BaseFormSet.is_valid of <django.forms.formsets.ItensPedidoFormFormSet object at 0x00000246782665C0>>
DEBUG:root:<bound method BaseFormSet.is_valid of <django.forms.formsets.ItensPedidoFormFormSet object at 0x00000246782642B0>>
ERROR:django.request:Internal Server Error: /pedido/ajax/tamanho
Traceback (most recent call last):
  File "c:\Projetos\venv\lib\site-packages\django\core\handlers\exception.py", line 55, in inner
    response = get_response(request)
  File "c:\Projetos\venv\lib\site-packages\django\core\handlers\base.py", line 197, in _get_response
    response = wrapped_callback(request, *callback_args, **callback_kwargs)
  File "C:\Projetos\InfoPizza\app\views.py", line 275, in load_tamanho
    tamanho = ItensPedido.objects.get(id=itensPedido_id).tamanho.id
  File "c:\Projetos\venv\lib\site-packages\django\db\models\manager.py", line 85, in manager_method
    return getattr(self.get_queryset(), name)(*args, **kwargs)
  File "c:\Projetos\venv\lib\site-packages\django\db\models\query.py", line 496, in get
    raise self.model.DoesNotExist(
app.models.ItensPedido.DoesNotExist: ItensPedido matching query does not exist.
ERROR:django.request:Internal Server Error: /pedido/ajax/tamanho
Traceback (most recent call last):
  File "c:\Projetos\venv\lib\site-packages\django\core\handlers\exception.py", line 55, in inner
    response = get_response(request)
  File "c:\Projetos\venv\lib\site-packages\django\core\handlers\base.py", line 197, in _get_response
    response = wrapped_callback(request, *callback_args, **callback_kwargs)
  File "C:\Projetos\InfoPizza\app\views.py", line 275, in load_tamanho
    tamanho = ItensPedido.objects.get(id=itensPedido_id).tamanho.id
  File "c:\Projetos\venv\lib\site-packages\django\db\models\manager.py", line 85, in manager_method
    return getattr(self.get_queryset(), name)(*args, **kwargs)
  File "c:\Projetos\venv\lib\site-packages\django\db\models\query.py", line 496, in get
    raise self.model.DoesNotExist(
app.models.ItensPedido.DoesNotExist: ItensPedido matching query does not exist.
DEBUG:root:<bound method BaseForm.is_valid of <PedidoForm bound=True, valid=Unknown, fields=(metodoPag;obs;cliente)>>
DEBUG:root:<bound method BaseFormSet.is_valid of <django.forms.formsets.ItensPedidoFormFormSet object at 0x00000127B0890A90>>
DEBUG:root:<bound method BaseFormSet.is_valid of <django.forms.formsets.ItensPedidoFormFormSet object at 0x00000127B0891C60>>
INFO:django.utils.autoreload:C:\Projetos\InfoPizza\app\views.py changed, reloading.
